Workbook
Name DPTPokBang: OFFSET('[1]U-EK'!$J$1,[1]HitBang!B1048576,0,[1]HitBang!B1)
Name Elev.: [1]Ref!$E$2:$E$14
Name Kec.: OFFSET([1]Adm_Wil!$L$8,1,0,[1]Adm_Wil!$L$8)
Name Kel.1: OFFSET([1]Adm_Wil!$H$9,VLOOKUP(List_DP!XFD1,[1]Adm_Wil!XEY$10:XFA$79,2,0),0,VLOOKUP(List_DP!XFD1,[1]Adm_Wil!$C$10:$E$79,3,0))
Name Kel.2: OFFSET([1]Adm_Wil!$G$9,VLOOKUP([1]Grand_Sum!XFD1,[1]Adm_Wil!$C$9:$K$146,8,0),1,VLOOKUP([1]Grand_Sum!XFD1,[1]Adm_Wil!$C$9:$J$146,7,0))
Name Kel_Acuan: OFFSET([1]Adm_Wil!$G$9,VLOOKUP([1]DP_Imaginer!XFD1,[1]Adm_Wil!$C$10:$E$79,2,0),1,VLOOKUP([1]DP_Imaginer!XFD1,[1]Adm_Wil!$C$10:$E$79,3,0))
Name Kokab.: OFFSET([1]IKK!$B$1,[1]Adm_Wil!$A$4,0,[1]Adm_Wil!$A$5)
Name PokBang: '[1]U-EK'!$J$3:$J$11
Name PROP.: [1]IKK!$I$4:$I$37
Name RUTR: [1]Ref!$F$2:$F$9
Name Tgl_Penilaian: List_DP!#REF!
Name Thn_Pajak: List_DP!#REF!
Name xxx: OFFSET([1]Adm_Wil!$H$9,VLOOKUP(List_DP!XFD1,[1]Adm_Wil!XEY$10:XFA$79,2,0),0,VLOOKUP(List_DP!XFD1,[1]Adm_Wil!$C$10:$E$79,3,0))

Sheet List_DP
A1: no | B1: jenis_properti | C1: alamat | D1: provinsi | E1: kota_kab | F1: kecamatan | G1: desa_kelurahan | H1: latlng | I1: luas_tanah | J1: luas_bangunan | K1: kisaran_nilai_tanah | L1: tanggal_data | M1: surveyor | N1: reviewer | O1: admin
A2: 1 | B2: Tanah Kosong | C2: Kawasan GIIC, Jl. Anggrek 2 | D2: Jawa Barat | E2: Kab. Bekasi | F2: Cikarang Pusat | G2: Nagasari | H2: -6.395972, 107.173722 | I2: 76007 | J2: 0 | K2: 2171000 | L2: 45635 | M2: Surveyor 1 | N2: Reviewer 1 | O2: AT
A3: 2 | B3: Tanah Kosong | C3: Kawasan GIIC, Jl. Anggrek Raya | D3: Jawa Barat | E3: Kab. Bekasi | F3: Cikarang Pusat | G3: Sukamahi | H3: -6.385667, 107.169389 | I3: 20000 | J3: 0 | K3: 2250000 | L3: 45635 | M3: Surveyor 1 | N3: Reviewer 1 | O3: AT
A4: 3 | B4: Tanah Kosong | C4: Kawasan GIIC, Jl. Edelweis | D4: Jawa Barat | E4: Kab. Bekasi | F4: Bojongmangu | G4: Sukamukti | H4: -6.397194, 107.185611 | I4: 80000 | J4: 0 | K4: 2313000 | L4: 45635 | M4: Surveyor 1 | N4: Reviewer 1 | O4: AT
A5: 4 | B5: Tanah & Bangunan | C5: Perumahan Pondok Indah, Jl Sekolah Kencana I Blok SH-3 No. 17 | D5: DKI Jakarta | E5: Kota Jakarta Selatan | F5: Kebayoran Lama | G5: Pondok Pinang | H5: -6.279330, 106.784497 | I5: 630 | J5: 600 | K5: 35278000 | L5: 45653 | M5: Surveyor 1 | N5: Reviewer 1 | O5: AT
A6: 5 | B6: Tanah & Bangunan | C6: Perumahan Pondok Indah, Jl Kencana Indah III No. 18 | D6: DKI Jakarta | E6: Kota Jakarta Selatan | F6: Kebayoran Lama | G6: Pondok Pinang | H6: -6.279291, 106.786859 | I6: 940 | J6: 800 | K6: 34731000 | L6: 45653 | M6: Surveyor 1 | N6: Reviewer 1 | O6: AT
A7: 6 | B7: Tanah & Bangunan | C7: Perumahan Pondok Indah, Jl Kencana Permai I Blok SN-18 No. 4 | D7: DKI Jakarta | E7: Kota Jakarta Selatan | F7: Kebayoran Lama | G7: Pondok Pinang | H7: -6.277632, 106.783506 | I7: 421 | J7: 500 | K7: 33298000 | L7: 45653 | M7: Surveyor 1 | N7: Reviewer 1 | O7: AT
A8: 7 | B8: Tanah Kosong | C8: Jl. Raya Pelabuhan Kabil | D8: Kepulauan Riau | E8: Kota Batam | F8: Nangsa | G8: Kabil | H8: 1,078611, 04.134472 | I8: 205600 | J8: 0 | K8: 972000 | L8: 45565 | M8: Surveyor 1 | N8: Reviewer 1 | O8: AT
A9: 8 | B9: Tanah Kosong | C9: Jl. Hang Kesturi, Komp. Kabil Industrial Estate | D9: Kepulauan Riau | E9: Kota Batam | F9: Nangsa | G9: Kabil | H9: 1,096908, 04.134577 | I9: 180000 | J9: 0 | K9: 889000 | L9: 45565 | M9: Surveyor 1 | N9: Reviewer 1 | O9: AT
A10: 9 | B10: Tanah & Bangunan | C10: Jl. Raya Pelabuhan Kabil (Kampung Baru) | D10: Kepulauan Riau | E10: Kota Batam | F10: Nangsa | G10: Kabil | H10: 1,055694, 04.137000 | I10: 100000 | J10: 16200 | K10: 1065000 | L10: 45565 | M10: Surveyor 1 | N10: Reviewer 1 | O10: AT
A11: 10 | B11: Tanah & Bangunan | C11: Jalan Untung Suropati | D11: Jawa Tengah | E11: Kota Semarang | F11: Ngaliyan | G11: Bambankerep | H11: -7.011861, 110.368222 | I11: 750 | J11: 350 | K11: 3466000 | L11: 45371 | M11: Surveyor 1 | N11: Reviewer 1 | O11: AT
A12: 11 | B12: Tanah Kosong | C12: Jalan Untung Suropati | D12: Jawa Tengah | E12: Kota Semarang | F12: Ngaliyan | G12: Bambankerep | H12: -7.012222, 110.367972 | I12: 1200 | J12: 0 | K12: 4200000 | L12: 45371 | M12: Surveyor 1 | N12: Reviewer 1 | O12: AT
A13: 12 | B13: Tanah Kosong | C13: Jalan Untung Suropati | D13: Jawa Tengah | E13: Kota Semarang | F13: Ngaliyan | G13: Bambankerep | H13: -7.012139, 110.370361 | I13: 832 | J13: 0 | K13: 3606000 | L13: 45371 | M13: Surveyor 1 | N13: Reviewer 1 | O13: AT
... A138: 137 | B138: Tanah & Bangunan | C138: Perumahan Sinar Pamulang Permai, Blok A-6 No. 9 | D138: Banten | E138: Kota Tangerang Selatan | F138: Pamulang | G138: Pamulang Barat | H138: -6.341361, 106.743083 | I138: 90 | J138: 80 | K138: 2448000 | L138: 45699 | M138: Surveyor 1 | N138: Reviewer 1 | O138: AT
A139: 138 | B139: Tanah & Bangunan | C139: Jalan oasis | D139: Nusa Tenggara Barat | E139: Kab. Lombok Barat | F139: Pamenang | G139: Gili Indah | H139: -8.359417, 116.085083 | I139: 2000 | J139: 600 | L139: 45672 | M139: Surveyor 1 | N139: Reviewer 1 | O139: AT
A140: 139 | B140: Tanah Kosong | C140: Jalan Karma | D140: Nusa Tenggara Barat | E140: Kab. Lombok Barat | F140: Pamenang | G140: Gili Indah | H140: -8.359139, 116.086083 | I140: 2221 | J140: 0 | K140: 2094000 | L140: 45672 | M140: Surveyor 1 | N140: Reviewer 1 | O140: AT
A141: 140 | B141: Tanah Kosong | C141: Jalan Sunset Boulevard | D141: Nusa Tenggara Barat | E141: Kab. Lombok Barat | F141: Pamenang | G141: Gili Indah | H141: -8.350611, 116.084306 | I141: 2079 | J141: 0 | K141: 2597000 | L141: 45672 | M141: Surveyor 1 | N141: Reviewer 1 | O141: AT
A142: 141 | B142: Tanah Kosong | C142: Jalan Desa Batu Nampar | D142: Nusa Tenggara Barat | E142: Kab. Lombok Barat | F142: Jerowaru | G142: Batunampar | H142: -8.846417, 116.396222 | I142: 100000 | J142: 0 | K142: 68000 | L142: 45672 | M142: Surveyor 1 | N142: Reviewer 1 | O142: AT
A143: 142 | B143: Tanah Kosong | C143: Jalan Desa Batu Nampar | D143: Nusa Tenggara Barat | E143: Kab. Lombok Barat | F143: Jerowaru | G143: Batunampar | H143: -8.838861, 116.411528 | I143: 293000 | J143: 0 | K143: 67000 | L143: 45672 | M143: Surveyor 1 | N143: Reviewer 1 | O143: AT
A144: 143 | B144: Tanah Kosong | C144: Jalan Desa | D144: Nusa Tenggara Barat | E144: Kab. Lombok Barat | F144: Jerowaru | G144: Batunampar | H144: -8.876472, 116.454056 | I144: 80000 | J144: 0 | K144: 80000 | L144: 45672 | M144: Surveyor 1 | N144: Reviewer 1 | O144: AT
A145: 144 | B145: Tanah & Bangunan | C145: Jl. Rawa Sawah 1 | D145: DKI Jakarta | E145: Kota Jakarta Pusat | F145: Johar Baru | G145: Galur | H145: -6.177474, 106.852192 | I145: 58 | J145: 55 | K145: 5659000 | L145: 45701 | M145: Surveyor 1 | N145: Reviewer 1 | O145: AT
A146: 145 | B146: Tanah & Bangunan | C146: Gang Biduri Anggur No. 18 | D146: DKI Jakarta | E146: Kota Jakarta Pusat | F146: Johar Baru | G146: Galur | H146: -6.175671, 106.853737 | I146: 57 | J146: 104 | K146: 2971000 | L146: 45701 | M146: Surveyor 1 | N146: Reviewer 1 | O146: AT
A147: 146 | B147: Tanah & Bangunan | C147: Gang Biduri Anggur No. 22 | D147: DKI Jakarta | E147: Kota Jakarta Pusat | F147: Johar Baru | G147: Galur | H147: -6.175669, 106.853773 | I147: 49 | J147: 70 | K147: 2984000 | L147: 45701 | M147: Surveyor 1 | N147: Reviewer 1 | O147: AT
A148: 147 | B148: Tanah Kosong | C148: Jalan Cendrawasih | D148: Jawa Barat | E148: Kab. Bekasi | F148: Serang | G148: Jayamulya | H148: -6.404969, 107.065282 | I148: 1965 | J148: 0 | K148: 1526000 | L148: 45716 | M148: Surveyor 1 | N148: Reviewer 1 | O148: AT
A149: 148 | B149: Tanah Kosong | C149: Jalan Cendrawasih | D149: Jawa Barat | E149: Kab. Bekasi | F149: Serang | G149: Jayamulya | H149: -6.404498, 107.065705 | I149: 1003 | J149: 0 | K149: 1794000 | L149: 45716 | M149: Surveyor 1 | N149: Reviewer 1 | O149: AT
A150: 149 | B150: Tanah Kosong | C150: Jalan Pasirandu | D150: Jawa Barat | E150: Kab. Bekasi | F150: Serang | G150: Jayamulya | H150: -6.396593, 107.079773 | I150: 631 | J150: 0 | K150: 1744000 | L150: 45716 | M150: Surveyor 1 | N150: Reviewer 1 | O150: AT
A151: 150 | B151: Tanah Kosong | C151: Jalan Abdul Majid Ibrahim | D151: Nanggroe Aceh Darussalam | E151: Kota Sabang | F151: Sukakarya | G151: Kuta Ateueh | H151: 5,891395, 5.323272 | I151: 1200 | J151: 0 | K151: 4001000 | L151: 45681 | M151: Surveyor 1 | N151: Reviewer 1 | O151: AT
... A190: 189 | B190: Tanah Kosong | C190: Jl. Laksamana Bintan | D190: Kepulauan Riau | E190: Kota Batam | F190: Batam Kota | G190: Belian | H190: 1,11575, 04.054972 | I190: 6000 | J190: 0 | K190: 3665000 | L190: 45618 | M190: Surveyor 2 | N190: Reviewer 2 | O190: GF
A191: 190 | B191: Tanah & Bangunan | C191: Jalan Yossudarso-Jalan Sudirman | D191: Kepulauan Riau | E191: Kota Batam | F191: Batam Kota | G191: Belian | H191: 1,126795, 04.016701 | I191: 10993 | J191: 19684 | L191: 45618 | M191: Surveyor 2 | N191: Reviewer 2 | O191: GF
A192: 191 | B192: Tanah & Bangunan | C192: Jalan Kelapa Puyuh III Blok KD No. 12A | D192: DKI Jakarta | E192: Kota Jakarta Utara | F192: Kelapa Gading | G192: kelapa Gading Timur | H192: -6.174167, 106.902111 | I192: 160 | J192: 170 | K192: 12101000 | L192: 45621 | M192: Surveyor 2 | N192: Reviewer 2 | O192: GF
A193: 192 | B193: Tanah & Bangunan | C193: Jalan Kelapa Molek IV Blok U2 | D193: DKI Jakarta | E193: Kota Jakarta Utara | F193: Kelapa Gading | G193: kelapa Gading Timur | H193: -6.172500, 106.903000 | I193: 111 | J193: 72 | K193: 12660000 | L193: 45621 | M193: Surveyor 2 | N193: Reviewer 2 | O193: GF
A194: 193 | B194: Tanah & Bangunan | C194: Jalan Kelapa Molek V Blok U-1 No. 4 | D194: DKI Jakarta | E194: Kota Jakarta Utara | F194: Kelapa Gading | G194: kelapa Gading Timur | H194: -6.172000, 106.902694 | I194: 102 | J194: 320 | K194: 10998000 | L194: 45621 | M194: Surveyor 2 | N194: Reviewer 2 | O194: GF
A195: 194 | B195: Tanah & Bangunan | C195: Perum Bekasi Timur Regency, Cluster Morganite Blok M2 No. 2 | D195: Jawa Barat | E195: Kab. Bekasi | F195: Setu | G195: Burangkeng | H195: -6.332250, 107.018722 | I195: 120 | J195: 85 | K195: 1331000 | L195: 45600 | M195: Surveyor 2 | N195: Reviewer 2 | O195: GF
A196: 195 | B196: Tanah & Bangunan | C196: Perum Bekasi Timur Regency, Cluster Morganite Blok M8 No. 3 | D196: Jawa Barat | E196: Kab. Bekasi | F196: Setu | G196: Burangkeng | H196: -6.332972, 107.018944 | I196: 120 | J196: 85 | K196: 1330000 | L196: 45600 | M196: Surveyor 2 | N196: Reviewer 2 | O196: GF
A197: 196 | B197: Tanah & Bangunan | C197: Jalan H. Hikmah | D197: Jawa Barat | E197: Kota Depok | F197: Pancoran Mas | G197: Rangkapan Jaya Baru | H197: -6.408389, 106.785889 | I197: 94 | J197: 100 | K197: 85000 | L197: 45607 | M197: Surveyor 2 | N197: Reviewer 2 | O197: GF
A198: 197 | B198: Tanah & Bangunan | C198: Gang H. Ncat | D198: Jawa Barat | E198: Kota Depok | F198: Beji | G198: Beji | H198: -6.387722, 106.815361 | I198: 100 | J198: 70 | K198: 1137000 | L198: 45594 | M198: Surveyor 2 | N198: Reviewer 2 | O198: GF
A199: 198 | B199: Tanah & Bangunan | C199: Gang Masjid Al Qubaiyah | D199: Jawa Barat | E199: Kota Depok | F199: Beji | G199: Beji | H199: -6.386278, 106.815889 | I199: 100 | J199: 80 | K199: 628000 | L199: 45594 | M199: Surveyor 2 | N199: Reviewer 2 | O199: GF
A200: 199 | B200: Tanah & Bangunan | C200: Jalan Kembang Lio | D200: Jawa Barat | E200: Kota Depok | F200: Pancoran Mas | G200: Depok | H200: -6.395194, 106.818611 | I200: 150 | J200: 120 | K200: 135000 | L200: 45594 | M200: Surveyor 2 | N200: Reviewer 2 | O200: GF
A201: 200 | B201: Tanah Kosong | C201: Jalan Cikeruh | D201: Jawa Barat | E201: Kab. Karawang | F201: Tirtajaya | G201: Cikeruh | H201: -6.046306, 107.206056 | I201: 720 | J201: 0 | K201: 239000 | L201: 45593 | M201: Surveyor 2 | N201: Reviewer 2 | O201: GF
A202: 201 | B202: Tanah Kosong | C202: Kampung Graha Mulya | D202: Jawa Barat | E202: Kab. Karawang | F202: Tirtajaya | G202: Cikeruh | H202: -6.060444, 107.228944 | I202: 420 | J202: 0 | K202: 214000 | L202: 45593 | M202: Surveyor 2 | N202: Reviewer 2 | O202: GF
...

Sheet Sheet1
A2: KECAMATAN | B2: KODE | C2: KELURAHAN/DESA | D2: LUAS (km²)*) | E2: SURVEYOR | F2: NO REKENING | G2: ANALIS | H2: NO REKENING | K2: =INDEX(Sheet1!$E$5:$E$21;MATCH(List_DP!F2;Sheet1!$C$5:$C$21;0)) | N2: KEL | O2: (All)
K4: SURVEYOR | L4: JUMLAH DATA | N4: Row Labels | O4: Count of JENIS PROPERTI
A5: Kuta (Luas 17,52 km2) | B5: 1001 | C5: Tuban | D5: 2.68 | E5: Ketut Agus Sudiartawan | F5: BCA 4350484111 | G5: I Komang Adi Juniarta | H5: Mandiri 1450013437633 | I5: =COUNTIF(List_DP!$G:$G,Sheet1!C5) -> 0 | K5: Wayan Juniarta | L5: =COUNTIF(List_DP!$O:$O,Sheet1!K5) -> 0 | N5: Tanah & Bangunan | O5: 180
B6: 1002 | C6: Kuta | D6: 7.23 | E6: I Ketut Pasek Sujiwa | F6: BCA 6690583672 | I6: =COUNTIF(List_DP!$G:$G,Sheet1!C6) -> 0 | K6: I Ketut Pasek Sujiwa | L6: =COUNTIF(List_DP!$O:$O,Sheet1!K6) -> 0 | N6: Tanah Kosong | O6: 692
B7: 1003 | C7: Kedonganan | D7: 1.91 | E7: Ketut Agus Sudiartawan | F7: BCA 4350484111 | I7: =COUNTIF(List_DP!$G:$G,Sheet1!C7) -> 0 | K7: Umroni Ahmadi | L7: =COUNTIF(List_DP!$O:$O,Sheet1!K7) -> 0 | N7: Tanah saja (bangunan diabaikan) | O7: 31
B8: 1004 | C8: Legian | D8: 3.05 | E8: Umroni Ahmadi | F8: Mandiri 1410010992287 | I8: =COUNTIF(List_DP!$G:$G,Sheet1!C8) -> 0 | K8: Ketut Agus Sudiartawan | L8: =COUNTIF(List_DP!$O:$O,Sheet1!K8) -> 0 | N8: Grand Total | O8: 903
B9: 1005 | C9: Seminyak | D9: 2.65 | E9: Umroni Ahmadi | F9: Mandiri 1410010992287 | I9: =COUNTIF(List_DP!$G:$G,Sheet1!C9) -> 0 | K9: Made Panji Anom | L9: =COUNTIF(List_DP!$O:$O,Sheet1!K9) -> 0
A10: Kuta Selatan (Luas 101,13 km2) | B10: 2001 | C10: Pecatu | D10: 26.41 | E10: Wayan Juniarta | F10: BCA 6690464134 | G10: Isti Surtikanti | H10: Mandiri 1450013709478 | I10: =COUNTIF(List_DP!$G:$G,Sheet1!C10) -> 0 | K10: Made Sulatra | L10: =COUNTIF(List_DP!$O:$O,Sheet1!K10) -> 0
B11: 2002 | C11: Ungasan | D11: 14.99 | E11: Made Panji Anom | F11: Permata 9816616880 | I11: =COUNTIF(List_DP!$G:$G,Sheet1!C11) -> 0 | K11: I Komang Pasek | L11: =COUNTIF(List_DP!$O:$O,Sheet1!K11) -> 0
B12: 2003 | C12: Kutuh | D12: 8.56 | E12: Wayan Juniarta | F12: BCA 6690464134 | I12: =COUNTIF(List_DP!$G:$G,Sheet1!C12) -> 0 | K12: Wayan Sudana | L12: =COUNTIF(List_DP!$O:$O,Sheet1!K12) -> 0
B13: 1004 | C13: Benoa | D13: 28.28 | E13: Made Panji Anom | F13: Permata 9816616880 | I13: =COUNTIF(List_DP!$G:$G,Sheet1!C13) -> 0 | K13: TOTAL | L13: =SUM(L5:L12) -> 0
B14: 1005 | C14: Tanjung Benoa | D14: 2.39 | E14: Made Sulatra | F14: BRI 472001010439538 | I14: =COUNTIF(List_DP!$G:$G,Sheet1!C14) -> 0
B15: 1006 | C15: Jimbaran | D15: 20.5 | E15: I Ketut Pasek Sujiwa | F15: BCA 6690583672 | I15: =COUNTIF(List_DP!$G:$G,Sheet1!C15) -> 0 | L15: =List_DP!#REF! -> #REF!
A16: Kuta Utara (Luas 33,86 km2) | B16: 1001 | C16: Kerobokan Kelod | D16: 5.26 | E16: Made Sulatra | F16: BRI 472001010439538 | G16: I Made Sutirta | H16: Mandiri 1450014287235 | I16: =COUNTIF(List_DP!$G:$G,Sheet1!C16) -> 0
B17: 1002 | C17: Kerobokan | D17: 5.42 | E17: I Komang Pasek | F17: BCA 6690350554 | I17: =COUNTIF(List_DP!$G:$G,Sheet1!C17) -> 0
B18: 1003 | C18: Kerobokan Kaja | D18: 5.3 | E18: I Komang Pasek | F18: BCA 6690350554 | I18: =COUNTIF(List_DP!$G:$G,Sheet1!C18) -> 0
B19: 2004 | C19: Tibubeneng | D19: 6.5 | E19: Wayan Sudana | F19: BRI 098501037704538 | I19: =COUNTIF(List_DP!$G:$G,Sheet1!C19) -> 0
B20: 2005 | C20: Canggu | D20: 5.23 | E20: Wayan Sudana | F20: BRI 098501037704538 | I20: =COUNTIF(List_DP!$G:$G,Sheet1!C20) -> 0
B21: 2006 | C21: Dalung | D21: 6.15 | E21: I Komang Pasek | F21: BCA 6690350554 | I21: =COUNTIF(List_DP!$G:$G,Sheet1!C21) -> 0
I22: =SUM(I5:I21) -> 0 | N22: Bulan I
N23: Kuta | O23: =20+10+10+5+16 -> 61
N24: Kuta Selatan | O24: =20+6+2+47+85 -> 160
N25: Kuta Utara | O25: =5+4+5+33+46+8 -> 101
N26: Jumlah | O26: =SUM(O23:O25) -> 322

Sheet Surveyor
B2: UMRONI AHMADI | G2: WAYAN JUNIARTA | L2: KETUT AGUS SUDIARTAWAN | Q2: I KETUT PASEK SUJIWA
B25: P 4632 YZ | G25: DK 3615 AEM | L25: DK 4667 TY | Q25: DK 4179 EU
B34: I KOMANG PASEK | G34: WAYAN SUDANA | L34: MADE SULATRA | Q34: MADE PANJI ANOM
B57: DK 3011 AAI | G57: DK 6647 ACW | L57: DK 4049 KC | Q57: DK5690 TE

Sheet Analis
B1: SKETSA ANALIS ZONASI KECAMATAN KUTA SELATAN | N1: DOKUMENTASI SURVEY HARGA PASAR TANAH | Z1: HASIL KUMPULAN DATA HARGA PASAR TANAH
B20: ZONASI DESA PECATU | H20: ZONASI DESA TANJUNG BENOA
B38: ZONASI DESA BENOA | H38: ZONASI DESA JIMBARAN
B56: ZONASI DESA KUTUH | H56: ZONASI DESA UNGASAN
B58: SKETSA ANALIS ZONASI KECAMATAN KUTA | N58: DOKUMENTASI SURVEY HARGA PASAR TANAH | Z58: HASIL KUMPULAN DATA HARGA PASAR TANAH
B77: ZONASI KELURAHAN TUBAN | H77: ZONASI KELURAHAN KUTA
B95: ZONASI KELURAHAN KEDONGANAN | H95: ZONASI KELURAHAN LEGIAN
B113: ZONASI KELURAHAN SEMINYAK
B114: SKETSA ANALIS ZONASI KECAMATAN KUTA UTARA | N114: DOKUMENTASI SURVEY HARGA PASAR TANAH | Z114: HASIL KUMPULAN DATA HARGA PASAR TANAH
B133: ZONASI DESA PECATU | H133: ZONASI DESA TANJUNG BENOA
B151: ZONASI DESA BENOA | H151: ZONASI DESA JIMBARAN
B169: ZONASI DESA KUTUH | H169: ZONASI DESA UNGASAN
